Workbook

Sheet Suivi chantiers
A1: Tableau de suivi de chantiers | G1: Mode d’emploi : renseigner les cellules en bleu. Les cellules calculées se mettent à jour automatiquement. | N1: Suivi OPR / clôture
A3: Réf. | B3: Nom du chantier | C3: Adresse | D3: Conducteur de travaux | E3: Montant base marché (€ HT) | F3: TS / avenants (€ HT) | G3: Montant marché révisé (€ HT) | H3: Situations facturées cumulées (€ HT) | I3: % facturé | J3: Total dépenses (€ HT) | K3: Marge brute estimée (€ HT) | L3: Solde à facturer (€ HT) | M3: Tâches à faire | N3: Date OPR prévue | O3: Date OPR réalisée | P3: Statut chantier | Q3: Priorité | R3: Dernière mise à jour | S3: Commentaires
A4: =#REF! -> #REF! | B4: =#REF! -> #REF! | C4: =#REF! -> #REF! | D4: =#REF! -> #REF! | E4: =#REF! -> #REF! | F4: =#REF! -> #REF! | G4: =#REF! -> #REF! | H4: =#REF! -> #REF! | ... Q4: =#REF! -> #REF!
A5: =#REF! -> #REF! | B5: =#REF! -> #REF! | C5: =#REF! -> #REF! | D5: =#REF! -> #REF! | E5: =#REF! -> #REF! | F5: =#REF! -> #REF! | G5: =#REF! -> #REF! | H5: =#REF! -> #REF! | ... Q5: =#REF! -> #REF!
A6: =#REF! -> #REF! | B6: =#REF! -> #REF! | C6: =#REF! -> #REF! | D6: =#REF! -> #REF! | E6: =#REF! -> #REF! | F6: =#REF! -> #REF! | G6: =#REF! -> #REF! | H6: =#REF! -> #REF! | ... Q6: =#REF! -> #REF!
A7: =#REF! -> #REF! | B7: =#REF! -> #REF! | C7: =#REF! -> #REF! | D7: =#REF! -> #REF! | E7: =#REF! -> #REF! | F7: =#REF! -> #REF! | G7: =#REF! -> #REF! | H7: =#REF! -> #REF! | ... Q7: =#REF! -> #REF!
A8: =#REF! -> #REF! | B8: =#REF! -> #REF! | C8: =#REF! -> #REF! | D8: =#REF! -> #REF! | E8: =#REF! -> #REF! | F8: =#REF! -> #REF! | G8: =#REF! -> #REF! | H8: =#REF! -> #REF! | ... Q8: =#REF! -> #REF!
A9: =CRF!B6 -> CRF | B9: =CRF!C6 -> CRF | C9: =CRF!D6 -> 6/8 rue Entroncamento 94350 Villiers-sur-Marne | D9: =CRF!E6 -> Mohsan MAHMOOD | E9: =CRF!F6 -> 929613.5 | F9: =CRF!G6 -> 88498.82 | G9: =CRF!H6 -> 1018112.3 | H9: =CRF!I6 -> 900789.04 | ... Q9: =CRF!R6 -> 0
A10: =#REF! -> #REF! | B10: =#REF! -> #REF! | C10: =#REF! -> #REF! | D10: =#REF! -> #REF! | E10: =#REF! -> #REF! | F10: =#REF! -> #REF! | G10: =#REF! -> #REF! | H10: =#REF! -> #REF! | ... Q10: =#REF! -> #REF!
A11: =#REF! -> #REF! | B11: =#REF! -> #REF! | C11: =#REF! -> #REF! | D11: =#REF! -> #REF! | E11: =#REF! -> #REF! | F11: =#REF! -> #REF! | G11: =#REF! -> #REF! | H11: =#REF! -> #REF! | ... Q11: =#REF! -> #REF!
A12: =#REF! -> #REF! | B12: =#REF! -> #REF! | C12: =#REF! -> #REF! | D12: =#REF! -> #REF! | E12: =#REF! -> #REF! | F12: =#REF! -> #REF! | G12: =#REF! -> #REF! | H12: =#REF! -> #REF! | ... Q12: =#REF! -> #REF!
A13: =#REF! -> #REF! | B13: =#REF! -> #REF! | C13: =#REF! -> #REF! | D13: =#REF! -> #REF! | E13: =#REF! -> #REF! | F13: =#REF! -> #REF! | G13: =#REF! -> #REF! | H13: =#REF! -> #REF! | ... Q13: =#REF! -> #REF!
A14: =#REF! -> #REF! | B14: =#REF! -> #REF! | C14: =#REF! -> #REF! | D14: =#REF! -> #REF! | E14: =#REF! -> #REF! | F14: =#REF! -> #REF! | G14: =#REF! -> #REF! | H14: =#REF! -> #REF! | ... Q14: =#REF! -> #REF!
A15: =#REF! -> #REF! | B15: =#REF! -> #REF! | C15: =#REF! -> #REF! | D15: =#REF! -> #REF! | E15: =#REF! -> #REF! | F15: =#REF! -> #REF! | G15: =#REF! -> #REF! | H15: =#REF! -> #REF! | ... Q15: =#REF! -> #REF!
A16: =#REF! -> #REF! | B16: =#REF! -> #REF! | C16: =#REF! -> #REF! | D16: =#REF! -> #REF! | E16: =#REF! -> #REF! | F16: =#REF! -> #REF! | G16: =#REF! -> #REF! | H16: =#REF! -> #REF! | ... Q16: =#REF! -> #REF!
A17: CH-014 | G17: =IFERROR(E17+F17,"") -> 0 | I17: =IFERROR(H17/G17,0) -> 0 | K17: =IFERROR(H17-J17,"") -> 0 | L17: =IFERROR(G17-H17,"") -> 0
A18: CH-015 | G18: =IFERROR(E18+F18,"") -> 0 | I18: =IFERROR(H18/G18,0) -> 0 | K18: =IFERROR(H18-J18,"") -> 0 | L18: =IFERROR(G18-H18,"") -> 0
A19: CH-016 | G19: =IFERROR(E19+F19,"") -> 0 | I19: =IFERROR(H19/G19,0) -> 0 | K19: =IFERROR(H19-J19,"") -> 0 | L19: =IFERROR(G19-H19,"") -> 0
A20: CH-017 | G20: =IFERROR(E20+F20,"") -> 0 | I20: =IFERROR(H20/G20,0) -> 0 | K20: =IFERROR(H20-J20,"") -> 0 | L20: =IFERROR(G20-H20,"") -> 0
A21: CH-018 | G21: =IFERROR(E21+F21,"") -> 0 | I21: =IFERROR(H21/G21,0) -> 0 | K21: =IFERROR(H21-J21,"") -> 0 | L21: =IFERROR(G21-H21,"") -> 0
A22: CH-019 | G22: =IFERROR(E22+F22,"") -> 0 | I22: =IFERROR(H22/G22,0) -> 0 | K22: =IFERROR(H22-J22,"") -> 0 | L22: =IFERROR(G22-H22,"") -> 0
A23: CH-020 | G23: =IFERROR(E23+F23,"") -> 0 | I23: =IFERROR(H23/G23,0) -> 0 | K23: =IFERROR(H23-J23,"") -> 0 | L23: =IFERROR(G23-H23,"") -> 0
A24: CH-021 | G24: =IFERROR(E24+F24,"") -> 0 | I24: =IFERROR(H24/G24,0) -> 0 | K24: =IFERROR(H24-J24,"") -> 0 | L24: =IFERROR(G24-H24,"") -> 0
A25: CH-022 | G25: =IFERROR(E25+F25,"") -> 0 | I25: =IFERROR(H25/G25,0) -> 0 | K25: =IFERROR(H25-J25,"") -> 0 | L25: =IFERROR(G25-H25,"") -> 0
A26: CH-023 | G26: =IFERROR(E26+F26,"") -> 0 | I26: =IFERROR(H26/G26,0) -> 0 | K26: =IFERROR(H26-J26,"") -> 0 | L26: =IFERROR(G26-H26,"") -> 0
A27: CH-024 | G27: =IFERROR(E27+F27,"") -> 0 | I27: =IFERROR(H27/G27,0) -> 0 | K27: =IFERROR(H27-J27,"") -> 0 | L27: =IFERROR(G27-H27,"") -> 0
A28: CH-025 | G28: =IFERROR(E28+F28,"") -> 0 | I28: =IFERROR(H28/G28,0) -> 0 | K28: =IFERROR(H28-J28,"") -> 0 | L28: =IFERROR(G28-H28,"") -> 0
... A33: CH-030 | G33: =IFERROR(E33+F33,"") -> 0 | I33: =IFERROR(H33/G33,0) -> 0 | K33: =IFERROR(H33-J33,"") -> 0 | L33: =IFERROR(G33-H33,"") -> 0
A35: Synthèse | B35: Nombre de chantiers saisis | C35: =COUNTA(B4:B33) -> 13 | N35: Repères de statut
B36: Montant marché révisé total (€ HT) | C36: =SUM(G4:G33) -> #REF! | N36: Préparation
B37: Situations facturées totales (€ HT) | C37: =SUM(H4:H33) -> #REF! | N37: En cours
B38: Dépenses totales (€ HT) | C38: =SUM(J4:J33) -> #REF! | N38: OPR à planifier
B39: Solde total à facturer (€ HT) | C39: =SUM(L4:L33) -> #REF! | N39: OPR réalisée
N40: Clôturé

Sheet CRF
B1: Fiche chantier – modèle à dupliquer
B2: Duplique cet onglet pour chaque chantier. Les cellules bleues sont à renseigner. La ligne de reporting ci-dessous peut être reliée à une ligne de la synthèse.
B4: Zone de reporting vers le tableau de synthèse
B5: Réf. | C5: Nom du chantier | D5: Adresse | E5: Conducteur de travaux | F5: Montant base marché (€ HT) | G5: TS / avenants (€ HT) | H5: Montant marché révisé (€ HT) | I5: Situations facturées cumulées (€ HT) | J5: % facturé | K5: Total dépenses (€ HT) | L5: Marge brute estimée (€ HT) | M5: Solde à facturer (€ HT) | N5: Tâches à faire (résumé) | O5: Date OPR prévue | P5: Date OPR réalisée | Q5: Statut chantier | R5: Priorité
B6: =B10 -> CRF | C6: =D10 -> CRF | D6: =B12 -> 6/8 rue Entroncamento 94350 Villiers-sur-Marne | E6: =J10 -> Mohsan MAHMOOD | F6: =B16 -> 929613.5 | G6: =D16 -> 88498.82 | H6: =IFERROR(F6+G6,"") -> 1018112.3 | I6: =SUM(F21:F34) -> 900789.04 | J6: =IFERROR(I6/H6,0) -> 0.88476391 | K6: =SUM(N39:N53) -> 613254.33 | L6: =IFERROR(I6-K6,"") -> 287534.71 | M6: =IFERROR(H6-I6,"") -> 117323.28 | N6: =C57 -> 0 | O6: =N10 -> 0 | P6: =P10 -> 0 | Q6: =N12 -> En cours | R6: =P12 -> 0
B8: 1. Informations générales
B9: Réf. chantier | D9: Nom du chantier | J9: Conducteur de travaux | N9: Date OPR prévue | P9: Date OPR réalisée
B10: CRF | D10: CRF | J10: Mohsan MAHMOOD
B11: Adresse du chantier | N11: Statut | P11: Priorité
B12: 6/8 rue Entroncamento 94350 Villiers-sur-Marne | N12: En cours
B14: 2. Données marché
B15: Montant base marché (€ HT) | D15: TS / avenants (€ HT) | F15: Montant marché révisé (€ HT) | H15: Objectif marge brute (€ HT) | J15: Commentaires marché / points contractuels
B16: 929613.5 | D16: 88498.82 | F16: =IFERROR(B16+D16,"") -> 1018112.3
B18: 3. Situations facturées
B20: Date | C20: N° situation | D20: Libellé | F20: Montant facturé (€ HT) | H20: Règlement / observation
B21: 45800 | C21: 1 | D21: Situation N° 01 | F21: 55240.18
B22: 45831 | C22: 2 | D22: Situation N° 02 | F22: 84978.08
B23: 45859 | C23: 3 | D23: Situation N° 03 | F23: 129012.13
B24: 45898 | C24: 4 | D24: Situation N° 04 | F24: 65246.58
B25: 45929 | C25: 5 | D25: Situation N° 05 | F25: 56104.41
B26: 45966 | C26: 6 | D26: Situation N° 06 | F26: 75411.35
B27: 45996 | C27: 7 | D27: Situation N° 07 | F27: 61478.68
B28: 46017 | C28: 8 | D28: Situation N° 08 | F28: 107726.24
B29: 46043 | C29: 9 | D29: Situation N° 09 | F29: 71211.91
B30: 46073 | C30: 10 | D30: Situation N° 10 | F30: 107760.65
B31: 46114 | C31: 11 | D31: Situation N° 11 | F31: 86618.83
D35: Total situations facturées | F35: =SUM(F21:F34) -> 900789.04 | H35: Ce total remonte automatiquement dans la zone de reporting.
B37: 4. Dépenses chantier
B38: Date | C38: Fournisseur | F38: Catégorie | H38: Libellé / détail | N38: Montant dépense (€ HT) | P38: Validé / observation
B39: 46129 | C39: ART CONCEPT | F39: Sous-traitant | H39: Achat matériels pour Fehmi PointP | N39: 41663.61
B40: 46129 | C40: ART CONCEPT | F40: Sous-traitant | H40: Achats divers | N40: =54478.35+1643.93+2096.69 -> 58218.97
B41: 46129 | C41: ART CONCEPT | F41: Sous-traitant | H41: Avances sur situations (virements) | N41: 281256.96
B42: 46129 | C42: BOB RENOV | F42: Fournisseur | H42: Mext | N42: 61366.99
B43: 46129 | C43: PCCR | F43: Sous-traitant | H43: Plomberie CVCPB | N43: 48742
B44: 46129 | C44: B6 CONCEPT | F44: Fournisseur | H44: BET | N44: 5850
B45: 46129 | C45: AA Ingénierie | F45: Fournisseur | H45: BET | N45: 2900
B46: 46129 | C46: Polybat | F46: Fournisseur | H46: RAVALEMENT | N46: 38844
B47: 46129 | C47: SENBAIE | F47: Fournisseur | H47: BSO | N47: 19000
B48: 46129 | C48: Copypage | F48: Fournisseur | H48: IMPRESSION PLANS | N48: 200
B49: 46129 | C49: FULFILER | F49: Fournisseur | H49: IMPRESSION PLANS | N49: 265
...

Sheet Listes
A1: Préparation | B1: Haute
A2: En cours | B2: Moyenne
A3: OPR à planifier | B3: Basse
A4: OPR réalisée
A5: Clôturé
