Workbook

Sheet BPU LOT 1
D1: ACCORD CADRE MONO-ATTRIBUTAIRE PAR LOT A BONS DE COMMANDE BORDEREAU DE PRIX UNITAIRES (BPU) LOT N°01 - Missions de diagnostics réglementaires sur l’ensemble du patrimoine de OPH AUBERVILLIERS : amiante, plomb, termites, Electricité, gaz, Etats des risques de pollution.
A2: Les dispositions techniques et organisationnelles des parapgraphes 1 à 6 sont compris dans les prix unitaires indiqués ci-dessous.
A3: PLOMB
A4: DIAGNOSTIC PLOMB : CONSTAT DE RISQUE D'EXPOSITION AU PLOMB (LOGEMENT)
A6: N° | B6: § CCTP | C6: Désignation | D6: Spécificités | E6: Unité | F6: Prix au logement en fonction du type de logement
F7: Type de Logement | G7: Code article | H7: Prix unitaire en € H.T.
A9: 1 | B9: 7.1 | C9: Réalisation du Constat de Risque d’Exposition au Plomb : Logement | D9: Compris cartographie d'étendue et photographies des éléments avec une peinture présentant une concentration en plomb > 1 mg/cm² | E9: Logement | F9: Chambre | G9: KLM001 | H9: 24
F10: F1 | G10: KLM002 | H10: 25
F11: F2 | G11: KLM003 | H11: 26
F12: F3 | G12: KLM004 | H12: 27
F13: F4 et plus | G13: KLM005 | H13: 28
A15: DIAGNOSTIC PLOMB : CONSTAT DE RISQUE D'EXPOSITION AU PLOMB (PARTIE COMMUNE)
A17: N° | B17: § CCTP | C17: Désignation | D17: En | E17: Unité | F17: Prix à l'ensemble immobilier en fonction du nombre de logements
F18: Nombre de logements | G18: Code article | H18: Prix unitaire en € H.T.
A20: 2 | B20: 7.1 | C20: Réalisation du Constat de Risque d’Exposition au Plomb : Groupe immobilier parties communes | D20: Compris cartographie d'étendue et photographies des éléments avec une peinture présentant une concentration en plomb > 1 mg/cm² Compris, sous-sol, enveloppe du bâtiment, annexes et extérieurs | E20: Ensemble Immobilier par ESI | F20: Ensemble Immobilier : ≤ 20 logements | G20: KLM006 | H20: 68
F21: Ensemble Immobilier : 20 < logements ≤ 50 | G21: KLM007 | H21: 98
F22: Ensemble Immobilier : 50 < logements ≤ 150 | G22: KLM008 | H22: 138
F23: Ensemble Immobilier : 150 < logements ≤ 300 | G23: KLM009 | H23: 188
F24: Tranche de 100 logements supp | G24: KLM010 | H24: 98
A25: RAPPORT DE REPERAGE PLOMB AVANT TRAVAUX/DEMOLITION - RPAT / RPAD
A26: N° | B26: § CCTP | C26: Désignation | D26: Spécificités | E26: Unité | F26: Prix unitaire en fonction du nombre de véhicules
F27: Nombre de véhicules | G27: Code article | H27: Prix unitaire en € H.T.
A29: 3 | B29: 7.1 | C29: Réalisation du Constat de Risque d’Exposition au Plomb : Parc de Stationnement | D29: Compris cartographie d'étendue et photographies des éléments avec une peinture présentant une concentration en plomb > 1 mg/cm² | E29: Parc de stationnement | F29: Inférieur à 100 places | G29: KLM011 | H29: 98
F30: De 101 à 250 places | G30: KLM012 | H30: 148
F31: Supérieur à 251 places | G31: KLM013 | H31: 188
A33: N° | B33: § CCTP | C33: Désignation | D33: Spécificités | E33: Unité | F33: Prix unitaire en fonction de la superficie
F34: Superficie | G34: Code article | H34: Prix unitaire en € H.T.
D35: Par Bâtiment
A36: 4 | B36: 7.1 | C36: Réalisation du Constat de Risque d’Exposition au Plomb : Local technique / Commerce / ERP / Local associatif / Local administratif de l'OPH / Loge gardien / Chaufferie | D36: Compris cartographie d'étendue et photographies des éléments avec une peinture présentant une concentration en plomb > 1 mg/cm² | E36: Local | F36: Local ≤ 10 m² | G36: KLM014 | H36: 58
F37: 10 m² < local ≤ 50 m² | G37: KLM015 | H37: 68
F38: 50 m² < local ≤ 100 m² | G38: KLM016 | H38: 88
F39: 100 m² < local ≤ 500 m² | G39: KLM017 | H39: 148
F40: local > 500 m² | G40: KLM018 | H40: 200
A44: AMIANTE
A46: DIAGNOSTIC AMIANTE LOGEMENT
A48: N° | B48: § CTTP | C48: Désignation | D48: Spécificités | E48: Unité | G48: Code article | H48: Prix unitaire en € H.T.
A51: 12 | B51: 7.4 | C51: Réalisation du Diagnostic Amiante Parties Privatives (DAPP) : Logement | D51: DAPP Rapport de repérage liste A avec évaluation de l'état de conservation | E51: l'unité | G51: KLM034 | H51: 17
A53: X | B53: 7.5 | C53: Mise à jour du Diagnostic Amiante Parties Privatives (DAPP) : Logement | D53: Mise à jour du DAPP comprenant la réalisation du rapport de repérage liste A avec l'évaluation périodique de l'état de conservation | E53: l'unité | G53: X | H53: 11
A55: X | B55: 7.5 | C55: Mise à jour du Diagnostic Amiante Parties Privatives (DAPP) sur base documentaire : Logement | D55: Mise à jour du DAPP sur la base des documents founis par le MOA : Rapport de repérage avant travaux Rapport fin de travaux désamiantage ou justificatif de recouvrement/encoffrement Examens visuels et/ou mesures d'epoussièrement de l'air Etc. | E55: l'unité | G55: X | H55: 10
A57: 13 | B57: 7.4 | C57: Complément Diagnostic Amiante Parties Privatives (DAPP) en plus d'un Diagnostic Amiante Avant Travaux : Logement | D57: DAPP Rapport de repérage liste A avec évaluation de l'état de conservation | E57: L'unité : à utiliser uniquement avec l'article N° 11 | G57: KLM035 | H57: 8
...

Sheet DQE LOT 1
D1: ACCORD CADRE MONO-ATTRIBUTAIRE PAR LOT A BONS DE COMMANDE DETAIL QUANTITATIF ESTIMATIF (DQE) LOT N°01 - Missions de diagnostics réglementaires sur l’ensemble du patrimoine de OPH AUBERVILLIERS : amiante, plomb, termites, Electricité, gaz, Etats des risques de pollution.
A2: Les dispositions techniques et organisationnelles des parapgraphes 1 à 6 sont compris dans les prix unitaires indiqués ci-dessous.
A3: PLOMB
A4: DIAGNOSTIC PLOMB : CONSTAT DE RISQUE D'EXPOSITION AU PLOMB (LOGEMENT)
A6: N° | B6: § CCTP | C6: Désignation | D6: Spécificités | E6: Unité | F6: Prix au logement en fonction du type de logement
F7: Type de Logement | G7: Code article | H7: Prix unitaire en € H.T. | I7: QTÉ annuelle estimative | J7: TOTAL € H.T.
A9: 1 | B9: 7.1 | C9: Réalisation du Constat de Risque d’Exposition au Plomb : Logement | D9: Compris cartographie d'étendue et photographies des éléments avec une peinture présentant une concentration en plomb > 1 mg/cm² | E9: Logement | F9: Chambre | G9: KLM001 | H9: ='BPU LOT 1'!H9 -> 24 | I9: 60 | J9: =I9*H9 -> 1440
F10: F1 | G10: KLM002 | H10: ='BPU LOT 1'!H10 -> 25 | I10: 100 | J10: =I10*H10 -> 2500
F11: F2 | G11: KLM003 | H11: ='BPU LOT 1'!H11 -> 26 | I11: 160 | J11: =I11*H11 -> 4160
F12: F3 | G12: KLM004 | H12: ='BPU LOT 1'!H12 -> 27 | I12: 200 | J12: =I12*H12 -> 5400
F13: F4 et plus | G13: KLM005 | H13: ='BPU LOT 1'!H13 -> 28 | I13: 150 | J13: =I13*H13 -> 4200
A15: DIAGNOSTIC PLOMB : CONSTAT DE RISQUE D'EXPOSITION AU PLOMB (PARTIE COMMUNE)
A17: N° | B17: § CCTP | C17: Désignation | D17: En | E17: Unité | F17: Prix à l'ensemble immobilier en fonction du nombre de logements
F18: Nombre de logements | G18: Code article | H18: Prix unitaire en € H.T. | I18: QTÉ annuelle estimative | J18: TOTAL € H.T.
A20: 2 | B20: 7.1 | C20: Réalisation du Constat de Risque d’Exposition au Plomb : Groupe immobilier parties communes | D20: Compris cartographie d'étendue et photographies des éléments avec une peinture présentant une concentration en plomb > 1 mg/cm² Compris, sous-sol, enveloppe du bâtiment, annexes et extérieurs | E20: Ensemble Immobilier par ESI | F20: Ensemble Immobilier : ≤ 20 logements | G20: KLM006 | H20: ='BPU LOT 1'!H20 -> 68 | I20: 5 | J20: =I20*H20 -> 340
F21: Ensemble Immobilier : 20 < logements ≤ 50 | G21: KLM007 | H21: ='BPU LOT 1'!H21 -> 98 | I21: 25 | J21: =I21*H21 -> 2450
F22: Ensemble Immobilier : 50 < logements ≤ 150 | G22: KLM008 | H22: ='BPU LOT 1'!H22 -> 138 | I22: 10 | J22: =I22*H22 -> 1380
F23: Ensemble Immobilier : 150 < logements ≤ 300 | G23: KLM009 | H23: ='BPU LOT 1'!H23 -> 188 | I23: 10 | J23: =I23*H23 -> 1880
F24: Tranche de 100 logements supp | G24: KLM010 | H24: ='BPU LOT 1'!H24 -> 98 | I24: 5 | J24: =I24*H24 -> 490
A25: RAPPORT DE REPERAGE PLOMB AVANT TRAVAUX/DEMOLITION - RPAT / RPAD
A26: N° | B26: § CCTP | C26: Désignation | D26: Spécificités | E26: Unité | F26: Prix unitaire en fonction du nombre de véhicules
F27: Nombre de véhicules | G27: Code article | H27: Prix unitaire en € H.T. | I27: QTÉ annuelle estimative | J27: TOTAL € H.T.
A29: 3 | B29: 7.1 | C29: Réalisation du Constat de Risque d’Exposition au Plomb : Parc de Stationnement | D29: Compris cartographie d'étendue et photographies des éléments avec une peinture présentant une concentration en plomb > 1 mg/cm² | E29: Parc de stationnement | F29: Inférieur à 100 places | G29: KLM011 | H29: ='BPU LOT 1'!H29 -> 98 | I29: 10 | J29: =I29*H29 -> 980
F30: De 101 à 250 places | G30: KLM012 | H30: ='BPU LOT 1'!H30 -> 148 | I30: 5 | J30: =I30*H30 -> 740
F31: Supérieur à 251 places | G31: KLM013 | H31: ='BPU LOT 1'!H31 -> 188 | I31: 5 | J31: =I31*H31 -> 940
A33: N° | B33: § CCTP | C33: Désignation | D33: Spécificités | E33: Unité | F33: Prix unitaire en fonction de la superficie
F34: Superficie | G34: Code article | H34: Prix unitaire en € H.T. | I34: QTÉ annuelle estimative | J34: TOTAL € H.T.
D35: Par Bâtiment
A36: 4 | B36: 7.1 | C36: Réalisation du Constat de Risque d’Exposition au Plomb : Local technique / Commerce / ERP / Local associatif / Local administratif de l'OPH / Loge gardien / Chaufferie | D36: Compris cartographie d'étendue et photographies des éléments avec une peinture présentant une concentration en plomb > 1 mg/cm² | E36: Local | F36: Local ≤ 10 m² | G36: KLM014 | H36: ='BPU LOT 1'!H36 -> 58 | I36: 5 | J36: =I36*H36 -> 290
F37: 10 m² < local ≤ 50 m² | G37: KLM015 | H37: ='BPU LOT 1'!H37 -> 68 | I37: 5 | J37: =I37*H37 -> 340
F38: 50 m² < local ≤ 100 m² | G38: KLM016 | H38: ='BPU LOT 1'!H38 -> 88 | I38: 10 | J38: =I38*H38 -> 880
F39: 100 m² < local ≤ 500 m² | G39: KLM017 | H39: ='BPU LOT 1'!H39 -> 148 | I39: 4 | J39: =I39*H39 -> 592
F40: local > 500 m² | G40: KLM018 | H40: ='BPU LOT 1'!H40 -> 200 | I40: 5 | J40: =I40*H40 -> 1000
A44: AMIANTE
A46: DIAGNOSTIC AMIANTE LOGEMENT
A48: N° | B48: § CTTP | C48: Désignation | D48: Spécificités | E48: Unité | G48: Code article | H48: Prix unitaire en € H.T. | I48: QTÉ annuelle estimative | J48: TOTAL € H.T.
A51: 12 | B51: 7.4 | C51: Réalisation du Diagnostic Amiante Parties Privatives (DAPP) : Logement | D51: DAPP Rapport de repérage liste A avec évaluation de l'état de conservation | E51: l'unité | G51: KLM034 | H51: ='BPU LOT 1'!H51 -> 17 | I51: 100 | J51: =I51*H51 -> 1700
A53: X | B53: 7.5 | C53: Mise à jour du Diagnostic Amiante Parties Privatives (DAPP) : Logement | D53: Mise à jour du DAPP comprenant la réalisation du rapport de repérage liste A avec l'évaluation périodique de l'état de conservation | E53: l'unité | G53: X | H53: ='BPU LOT 1'!H53 -> 11 | I53: 100 | J53: =I53*H53 -> 1100
A55: X | B55: 7.5 | C55: Mise à jour du Diagnostic Amiante Parties Privatives (DAPP) sur base documentaire : Logement | D55: Mise à jour du DAPP sur la base des documents founis par le MOA : Rapport de repérage avant travaux Rapport fin de travaux désamiantage ou justificatif de recouvrement/encoffrement Examens visuels et/ou mesures d'epoussièrement de l'air Etc. | E55: l'unité | G55: X | H55: ='BPU LOT 1'!H55 -> 10 | I55: 50 | J55: =I55*H55 -> 500
A57: 13 | B57: 7.4 | C57: Complément Diagnostic Amiante Parties Privatives (DAPP) en plus d'un Diagnostic Amiante Avant Travaux : Logement | D57: DAPP Rapport de repérage liste A avec évaluation de l'état de conservation | E57: L'unité : à utiliser uniquement avec l'article N° 11 | G57: KLM035 | H57: ='BPU LOT 1'!H57 -> 8 | I57: 100 | J57: =I57*H57 -> 800
...
